Dataset not found , missing paths ['F:\\industry-dection\\datasets\\coco128\\images\\train2017']
Downloading https://ultralytics.com/assets/coco128.zip to coco128.zip...
Traceback (most recent call last):
  File "f:\industry-dection\yolov5\train.py", line 634, in <module>
    main(opt)
  File "f:\industry-dection\yolov5\train.py", line 528, in main
    train(opt.hyp, opt, device, callbacks)
  File "f:\industry-dection\yolov5\train.py", line 93, in train
    loggers = Loggers(save_dir, weights, opt, hyp, LOGGER)  # loggers instance
  File "f:\industry-dection\yolov5\utils\loggers\__init__.py", line 111, in __init__
    self.wandb = WandbLogger(self.opt, run_id)
  File "f:\industry-dection\yolov5\utils\loggers\wandb\wandb_utils.py", line 192, in __init__
    self.data_dict = check_wandb_dataset(opt.data)
  File "f:\industry-dection\yolov5\utils\loggers\wandb\wandb_utils.py", line 59, in check_wandb_dataset
    return check_dataset(data_file)
  File "f:\industry-dection\yolov5\utils\general.py", line 517, in check_dataset
    torch.hub.download_url_to_file(s, f)
  File "E:\AppInstall\Anaconda3\envs\pytorch\lib\site-packages\torch\hub.py", line 593, in download_url_to_file
    u = urlopen(req)
  File "E:\AppInstall\Anaconda3\envs\pytorch\lib\urllib\request.py", line 214, in urlopen
    return opener.open(url, data, timeout)
  File "E:\AppInstall\Anaconda3\envs\pytorch\lib\urllib\request.py", line 523, in open
    response = meth(req, response)
  File "E:\AppInstall\Anaconda3\envs\pytorch\lib\urllib\request.py", line 632, in http_response
    response = self.parent.error(
  File "E:\AppInstall\Anaconda3\envs\pytorch\lib\urllib\request.py", line 555, in error
    result = self._call_chain(*args)
  File "E:\AppInstall\Anaconda3\envs\pytorch\lib\urllib\request.py", line 494, in _call_chain
    result = func(*args)
  File "E:\AppInstall\Anaconda3\envs\pytorch\lib\urllib\request.py", line 747, in http_error_302
    return self.parent.open(new, timeout=req.timeout)
  File "E:\AppInstall\Anaconda3\envs\pytorch\lib\urllib\request.py", line 517, in open
    response = self._open(req, data)
  File "E:\AppInstall\Anaconda3\envs\pytorch\lib\urllib\request.py", line 534, in _open
    result = self._call_chain(self.handle_open, protocol, protocol +
  File "E:\AppInstall\Anaconda3\envs\pytorch\lib\urllib\request.py", line 494, in _call_chain
    result = func(*args)
  File "E:\AppInstall\Anaconda3\envs\pytorch\lib\urllib\request.py", line 1389, in https_open
    return self.do_open(http.client.HTTPSConnection, req,
  File "E:\AppInstall\Anaconda3\envs\pytorch\lib\urllib\request.py", line 1350, in do_open
    r = h.getresponse()
  File "E:\AppInstall\Anaconda3\envs\pytorch\lib\http\client.py", line 1377, in getresponse
    response.begin()
  File "E:\AppInstall\Anaconda3\envs\pytorch\lib\http\client.py", line 320, in begin
    version, status, reason = self._read_status()
  File "E:\AppInstall\Anaconda3\envs\pytorch\lib\http\client.py", line 281, in _read_status
    line = str(self.fp.readline(_MAXLINE + 1), "iso-8859-1")
  File "E:\AppInstall\Anaconda3\envs\pytorch\lib\socket.py", line 704, in readinto
    return self._sock.recv_into(b)
  File "E:\AppInstall\Anaconda3\envs\pytorch\lib\ssl.py", line 1242, in recv_into
    return self.read(nbytes, buffer)
  File "E:\AppInstall\Anaconda3\envs\pytorch\lib\ssl.py", line 1100, in read
    return self._sslobj.read(len, buffer)
TimeoutError: [WinError 10060] 由于连接方在一段时间后没有正确答复或连接的主机没有反应，连接尝试失败。